Workbook

Sheet Plan1
A1: 17136 | B1: 45498 | E1: Mastgen | I1: 3 | K1: 45500 | L1: 3 | M1: 45504 | P1: PE
A2: 2513 | B2: 45498 | E2: Promastic | I2: 5 | K2: 45502 | L2: 3 | M2: 45506 | N2: AE
A3: 3554 | B3: 45498 | E3: Promastic | I3: 5 | K3: 45502 | L3: 3 | M3: 45506 | N3: AE
A4: 3164 | B4: 45498 | E4: Promastic | I4: 5 | K4: 45502 | L4: 3 | M4: 45506 | N4: AE
A5: 2324 | B5: 45498 | E5: Promastic | I5: 5 | K5: 45502 | L5: 3 | M5: 45506 | Q5: PD
A6: 2050 | B6: 45498 | E6: Promastic | I6: 5 | K6: 45502 | L6: 3 | M6: 45506 | N6: AE
A7: 2879 | B7: 45499 | E7: Mastgen | I7: 5 | K7: 45503 | L7: 3 | M7: 45507 | O7: AD
A8: 2745 | B8: 45499 | E8: Ubrolexin | I8: 4 | K8: 45503 | L8: 5 | M8: 45509 | N8: AE | O8: AD | P8: PE
A9: 3637 | B9: 45499 | E9: Mastite clinica | I9: 5 | K9: 45503 | L9: 3 | M9: 45507 | O9: AD
A10: 3720 | B10: 45500 | E10: Mastite clinica | I10: 5 | K10: 45504 | L10: 3 | M10: 45508 | N10: AE | O10: AD | P10: PE | Q10: PD
A11: 873 | B11: 45501 | E11: Vetmax | I11: 5 | K11: 45505 | L11: 4 | M11: 45510 | N11: AE | O11: AD | P11: PE | Q11: PD
A12: 2959 | B12: 45501 | E12: Mastclin | I12: 5 | K12: 45505 | L12: 2 | M12: 45508 | N12: AE | O12: AD | Q12: PD
A13: 2513 | B13: 45502 | E13: Mastite clinica | I13: 5 | K13: 45506 | L13: 3 | M13: 45510 | O13: AD
A14: 2513 | B14: 45502 | E14: Promastic | I14: 5 | K14: 45506 | L14: 3 | M14: 45510 | O14: AD
A15: 2814 | B15: 45503 | E15: Mastite clinica | I15: 5 | K15: 45507 | L15: 3 | M15: 45511 | O15: AD
A16: 3459 | B16: 45503 | E16: Mastite clinica | I16: 5 | K16: 45507 | L16: 3 | M16: 45511 | N16: AE | P16: PE
A17: 2225 | B17: 45503 | E17: Mastite clinica | I17: 5 | K17: 45507 | L17: 3 | M17: 45511 | N17: AE
A18: 99 | B18: 45503 | E18: Mastite clinica | I18: 5 | K18: 45507 | L18: 3 | M18: 45511 | O18: AD | Q18: PD
A19: 2732 | B19: 45503 | E19: Mastite clinica | I19: 5 | K19: 45507 | L19: 3 | M19: 45511 | O19: AD
A20: 3164 | B20: 45504 | E20: Promastic | I20: 5 | K20: 45508 | L20: 3 | M20: 45512 | N20: AE
A21: 3323 | B21: 45504 | E21: Mastigem | I21: 5 | K21: 45508 | L21: 3 | M21: 45512 | N21: AE | P21: PE
A22: 3668 | B22: 45504 | E22: Mastigem | I22: 5 | K22: 45508 | L22: 3 | M22: 45512 | Q22: PD
A23: 3021 | B23: 45504 | E23: Ubroletin | I23: 5 | K23: 45508 | L23: 5 | M23: 45514 | N23: AE
A24: 1111 | B24: 45504 | E24: Mastite clinica | I24: 5 | K24: 45508 | L24: 3 | M24: 45512 | N24: AE | O24: AD | P24: PE | Q24: PD
A25: 1810 | B25: 45504 | E25: Mastite clinica | I25: 5 | K25: 45509 | L25: 3 | M25: 45512 | Q25: PD
A26: 2745 | B26: 45504 | E26: Promash | I26: 6 | K26: 45508 | L26: 3 | M26: 45513 | N26: AE | O26: AD | P26: PE | Q26: PD
A27: 3637 | B27: 45504 | E27: Mastgen | I27: 5 | K27: 45508 | L27: 3 | M27: 45512 | O27: AD
A28: 3467 | B28: 45504 | E28: Mastite clinica | F28: Mastite clinica | G28: Mastite clinica | H28: Mastite clinica | I28: 5 | K28: 45509 | L28: 3 | M28: 45512 | Q28: PD
A29: 1066 | B29: 45505 | E29: Mastite clinica | I29: 5 | K29: 45509 | L29: 3 | M29: 45513 | Q29: PD
A30: 2513 | B30: 45505 | E30: Mastite clinica | I30: 5 | K30: 45509 | L30: 3 | M30: 45513 | O30: AD
A31: 873 | B31: 45505 | E31: Mastgen | I31: 5 | K31: 45509 | L31: 3 | M31: 45513 | N31: AE | O31: AD | P31: PE | Q31: PD
A32: 2879 | B32: 45505 | E32: Mastgen | I32: 5 | K32: 45510 | L32: 3 | M32: 45513 | O32: AD
A33: 859 | B33: 45506 | E33: Mastite clinica | I33: 5 | K33: 45508 | L33: 3 | M33: 45514 | O33: AD
A34: 3079 | B34: 45506 | E34: Mastite clinica | I34: 3 | K34: 45510 | L34: 3 | M34: 45512 | N34: AE
A35: 1226 | B35: 45511 | E35: Promastic | I35: 5 | K35: 45510 | L35: 3 | M35: 45514 | O35: AD | Q35: PD
A36: 3034 | B36: 45511 | E36: Mastgen | I36: 5 | K36: 45510 | L36: 3 | M36: 45514 | N36: AE
A37: 2959 | B37: 45511 | E37: Promastic | I37: 5 | K37: 45510 | L37: 3 | M37: 45514 | P37: PE | Q37: PD
A38: 848 | B38: 45506 | E38: Mastite clinica | I38: 5 | K38: 45510 | L38: 3 | M38: 45514 | Q38: PD
A39: 3012 | B39: 45507 | E39: Rilexine | I39: 5 | K39: 45511 | L39: 5 | M39: 45517 | O39: AD
A40: 3819 | B40: 45507 | E40: Mastgen | I40: 5 | K40: 45511 | L40: 3 | M40: 45515 | Q40: PD
...

Sheet 2023
A1: VACA | B1: INÍCIO TRATAMENTO | C1: INTRAMÁMARIO | D1: DIAS APLICAÇÃO
A2: 1354 | B2: 44927 | C2: mastijet | D2: 3 | E2: 44929 | F2: 9 | G2: 44939 | J2: PE
A3: 1613 | B3: 44927 | C3: mastijet | D3: 5 | E3: 44931 | F3: 9 | G3: 44941 | I3: AD
A4: 2781 | B4: 44927 | C4: mastijet | D4: 5 | E4: 44931 | F4: 9 | G4: 44941 | K4: PD
A5: 3094 | B5: 44927 | C5: ciprolac | D5: 5 | E5: 44931 | F5: 3 | G5: 44935 | J5: PE
A6: 456 | B6: 44929 | C6: mastijet | D6: 5 | E6: 44933 | F6: 9 | G6: 44943 | I6: AD
A7: 1786 | B7: 44929 | C7: vetmax | D7: 5 | E7: 44933 | F7: 9 | G7: 44943 | H7: AE | J7: PE
A8: 1899 | B8: 44929 | C8: vetimax | D8: 5 | E8: 44933 | F8: 4 | G8: 44938 | I8: AD
A9: 1059 | B9: 44930 | C9: mastijet | D9: 3 | E9: 44932 | F9: 9 | G9: 44942 | I9: AD
A10: 1848 | B10: 44930 | C10: vetimax | D10: 5 | E10: 44934 | F10: 4 | G10: 44939 | K10: PD
A11: 2271 | B11: 44930 | C11: mastite clinica | D11: 5 | E11: 44934 | F11: 3 | G11: 44938 | I11: AD
A12: 2568 | B12: 44930 | C12: mastite clinica | D12: 5 | E12: 44934 | F12: 3 | G12: 44938 | H12: AE | I12: AD
A13: 3093 | B13: 44930 | C13: mastijet | D13: 3 | E13: 44932 | F13: 9 | G13: 44942 | H13: AE | J13: PE
A14: 1630 | B14: 44931 | C14: vetmax | D14: 5 | E14: 44935 | F14: 4 | G14: 44940 | K14: PD
A15: 1871 | B15: 44931 | C15: mastite clinica | D15: 5 | E15: 44935 | F15: 3 | G15: 44939 | H15: AE | I15: AD
A16: 2115 | B16: 44931 | C16: mastite clinica | D16: 5 | E16: 44935 | F16: 3 | G16: 44939 | I16: AD
A17: 2225 | B17: 44931 | C17: vetmax | D17: 5 | E17: 44935 | F17: 4 | G17: 44940 | I17: AD
A18: 3323 | B18: 44931 | C18: mastijet | D18: 5 | E18: 44935 | F18: 9 | G18: 44945 | K18: PD
A19: 154 | B19: 44932 | C19: ciprolac | D19: 5 | E19: 44936 | F19: 3 | G19: 44940 | H19: AE
A20: 993 | B20: 44932 | C20: mastijet | D20: 5 | E20: 44936 | F20: 9 | G20: 44946 | H20: AE
A21: 1874 | B21: 44932 | C21: mastijet | D21: 5 | E21: 44936 | F21: 9 | G21: 44946 | K21: PD
A22: 2440 | B22: 44932 | C22: ciprolac | D22: 5 | E22: 44936 | F22: 3 | G22: 44940 | H22: AE
A23: 1119 | B23: 44934 | C23: mastijet | D23: 5 | E23: 44938 | F23: 9 | G23: 44948 | K23: PD
A24: 1216 | B24: 44934 | C24: vetimax | D24: 5 | E24: 44938 | F24: 4 | G24: 44943 | I24: AD
A25: 2506 | B25: 44934 | C25: mastite clinica | D25: 5 | E25: 44938 | F25: 3 | G25: 44942 | I25: AD
A26: 2793 | B26: 44934 | C26: mastijet | D26: 5 | E26: 44938 | F26: 9 | G26: 44948 | I26: AD
A27: 194 | B27: 44935 | C27: mastijet | D27: 5 | E27: 44939 | F27: 9 | G27: 44949 | H27: AE
A28: 1059 | B28: 44935 | C28: newmast | D28: 5 | E28: 44939 | F28: 3 | G28: 44943 | I28: AD
A29: 1458 | B29: 44935 | C29: vetimax | D29: 3 | E29: 44937 | F29: 4 | G29: 44942 | J29: PE
A30: 2054 | B30: 44935 | C30: mastijet | D30: 5 | E30: 44939 | F30: 9 | G30: 44949 | H30: AE
A31: 2271 | B31: 44935 | C31: mastijet | D31: 5 | E31: 44939 | F31: 9 | G31: 44949 | I31: AD
A32: 2907 | B32: 44935 | C32: vetimax | D32: 5 | E32: 44939 | F32: 4 | G32: 44944 | H32: AE
A33: 3074 | B33: 44935 | C33: vetimax | D33: 5 | E33: 44939 | F33: 4 | G33: 44944 | J33: PE
A34: 3093 | B34: 44935 | C34: newmast | D34: 5 | E34: 44939 | F34: 3 | G34: 44943 | J34: PE
A35: 10 | B35: 44937 | C35: mastijet | D35: 5 | E35: 44941 | F35: 9 | G35: 44951 | H35: AE | J35: PE
A36: 1894 | B36: 44937 | C36: mastijet | D36: 5 | E36: 44941 | F36: 9 | G36: 44951 | K36: PD
A37: 2225 | B37: 44938 | C37: vetimax | D37: 5 | E37: 44942 | F37: 4 | G37: 44947 | I37: AD
A38: 3395 | B38: 44939 | C38: mastijet | D38: 5 | E38: 44943 | F38: 9 | G38: 44953 | J38: PE
A39: 1630 | B39: 44940 | C39: newmast | D39: 5 | E39: 44944 | F39: 3 | G39: 44948 | K39: PD
A40: 1662 | B40: 44940 | C40: mastijet | D40: 5 | E40: 44944 | F40: 9 | G40: 44954 | J40: PE
...

Sheet 2024
A1: VACA | B1: INÍCIO TRATAMENTO | D1: INTRAMAMÁRIO | F1: DIAS APLICAÇÃO | H1: FINAL TRATAMENTO | I1: CARÊNCIA | J1: FINAL TRATAMENTO | K1: TETO EM TRATAMENTO
A2: 1206 | B2: 45294 | D2: Mastite clinica | F2: 5 | H2: 45298 | I2: 3 | J2: 45302 | M2: PE
A3: 3031 | B3: 45294 | D3: Mastite clinica | F3: 5 | H3: 45298 | I3: 3 | J3: 45302 | K3: AE | L3: AD | M3: PE | N3: PD
A4: 2108 | B4: 45295 | D4: Ubrolexin | F4: 5 | H4: 45299 | I4: 5 | J4: 45305 | L4: AD | M4: PE
A5: 573 | B5: 45295 | D5: Mastite clinica | F5: 5 | H5: 45299 | I5: 3 | J5: 45303 | M5: PE
A6: 3172 | B6: 45295 | D6: Mastite clinica | F6: 5 | H6: 45299 | I6: 3 | J6: 45303 | K6: AE
A7: 3307 | B7: 45296 | D7: Ubrolexin | F7: 5 | H7: 45300 | I7: 5 | J7: 45306 | K7: AE
A8: 2020 | B8: 45296 | D8: Mastite clinica | F8: 5 | H8: 45300 | I8: 3 | J8: 45304 | K8: AE | L8: AD
A9: 2238 | B9: 45296 | D9: Mastite clinica | F9: 5 | H9: 45300 | I9: 3 | J9: 45304 | K9: AE | L9: AD | M9: PE | N9: PD
A10: 2716 | B10: 45296 | D10: Mastite clinica | F10: 5 | H10: 45300 | I10: 3 | J10: 45304 | K10: AE | L10: AD | N10: PD
A11: 3054 | B11: 45296 | D11: Mastite clinica | F11: 5 | H11: 45300 | I11: 3 | J11: 45304 | K11: AE | N11: PD
A12: 1180 | B12: 45296 | D12: Mastite clinica | F12: 5 | H12: 45300 | I12: 3 | J12: 45304 | L12: AD | N12: PD
A13: 3568 | B13: 45296 | D13: Mastite clinica | F13: 5 | H13: 45300 | I13: 3 | J13: 45304 | K13: AE | L13: AD | N13: PD
A14: 3309 | B14: 45296 | D14: Masticlim | F14: 5 | H14: 45300 | I14: 3 | J14: 45304 | N14: PD
A15: 2943 | B15: 45297 | D15: Mastite clinica | F15: 5 | H15: 45301 | I15: 3 | J15: 45305 | N15: PD
A16: 583 | B16: 45297 | D16: Mastite clinica | F16: 5 | H16: 45301 | I16: 3 | J16: 45305 | K16: AE
A17: 2791 | B17: 45297 | D17: Ubrolexin | F17: 5 | H17: 45301 | I17: 5 | J17: 45307 | K17: AE
A18: 2518 | B18: 45299 | D18: Mastite clinica | F18: 5 | H18: 45303 | I18: 3 | J18: 45307 | K18: AE | L18: AD
A19: 3065 | B19: 45299 | D19: Mastite clinica | F19: 5 | H19: 45303 | I19: 3 | J19: 45307 | L19: AD
A20: 2512 | B20: 45300 | D20: Mastite clinica | F20: 5 | H20: 45304 | I20: 3 | J20: 45308 | K20: AE | M20: PE | N20: PD
A21: 3055 | B21: 45301 | D21: Masticlim | F21: 5 | H21: 45305 | I21: 3 | J21: 45309 | L21: AD
A22: 2276 | B22: 45301 | D22: Masticlim | F22: 5 | H22: 45305 | I22: 3 | J22: 45309 | K22: AE | M22: PE | N22: PD
A23: 2917 | B23: 45301 | D23: Mastite clinica | F23: 5 | H23: 45305 | I23: 3 | J23: 45309 | L23: AD
A24: 2020 | B24: 45302 | D24: Masticlim | F24: 5 | H24: 45306 | I24: 3 | J24: 45310 | K24: AE
A25: 513 | B25: 45302 | D25: Masticlim | F25: 5 | H25: 45306 | I25: 3 | J25: 45310 | M25: PE
A26: 3568 | B26: 45302 | D26: Masticlim | F26: 5 | H26: 45306 | I26: 3 | J26: 45310 | K26: AE | L26: AD | M26: PE | N26: PD
A27: 2789 | B27: 45302 | D27: Mastite clinica | F27: 5 | H27: 45306 | I27: 3 | J27: 45310 | M27: PE
A28: 588 | B28: 45302 | D28: Masticlim | F28: 5 | H28: 45306 | I28: 3 | J28: 45310 | M28: PE | N28: PD
A29: 1180 | B29: 45304 | D29: Ubrolexin | F29: 5 | H29: 45308 | I29: 5 | J29: 45314 | L29: AD
A30: 1208 | B30: 45304 | D30: Mastite clinica | F30: 5 | H30: 45308 | I30: 3 | J30: 45312 | K30: AE | N30: PD
A31: 1166 | B31: 45304 | D31: Mastite clinica | F31: 5 | H31: 45308 | I31: 3 | J31: 45312 | N31: PD
A32: 2933 | B32: 45304 | D32: Mastite clinica | F32: 5 | H32: 45308 | I32: 3 | J32: 45312 | K32: AE
A33: 583 | B33: 45304 | D33: Mastijet | F33: 5 | H33: 45308 | I33: 9 | J33: 45318 | K33: AE
A34: 3368 | B34: 45304 | D34: Mastijet | F34: 5 | H34: 45308 | I34: 9 | J34: 45318 | K34: AE
A35: 2594 | B35: 45304 | D35: Cobactam | F35: 5 | H35: 45308 | I35: 3 | J35: 45312 | K35: AE | L35: AD | N35: PD
A36: 588 | B36: 45304 | D36: Mastijet | F36: 5 | H36: 45308 | I36: 9 | J36: 45318 | M36: PE | N36: PD
A37: 2716 | B37: 45307 | D37: Mastite clinica | F37: 5 | H37: 45311 | I37: 3 | J37: 45315 | K37: AE | L37: AD
A38: 2410 | B38: 45307 | D38: Mastite clinica | F38: 5 | H38: 45311 | I38: 3 | J38: 45315 | K38: AE
A39: 1206 | B39: 45307 | D39: vetimax | F39: 5 | H39: 45311 | I39: 3 | J39: 45315 | K39: AE
A40: 2276 | B40: 45307 | D40: vetimax | F40: 5 | H40: 45311 | I40: 3 | J40: 45315 | K40: AE | L40: AD | M40: PE | N40: PD
...

Sheet 2025
A1: VACA | B1: INÍCIO TRATAMENTO | D1: INTRAMAMÁRIO | F1: DIAS APLICAÇÃO | H1: FINAL TRATAMENTO | I1: CARÊNCIA | J1: FINAL TRATAMENTO | K1: TETO EM TRATAMENTO
A2: 3677 | B2: 45658 | D2: Mastite clinica | F2: 5 | H2: =B2+F2-1 -> 45662 | I2: 3 | J2: =H2+I2+1 -> 45666 | K2: AE
A3: 3705 | B3: 45659 | D3: Mastite clinica | F3: 5 | H3: =B3+F3-1 -> 45663 | I3: 3 | J3: =H3+I3+1 -> 45667 | M3: PE
A4: 3863 | B4: 1 | D4: Mastite clinica | F4: 5 | H4: =B4+F4-1 -> 5 | I4: 3 | J4: =H4+I4+1 -> 9 | K4: AE
A5: 2193 | B5: 45660 | D5: Mast jet | F5: 5 | H5: =B5+F5-1 -> 45664 | I5: 9 | J5: =H5+I5+1 -> 45674 | L5: AD
A6: 3211 | B6: 45661 | D6: Mast jet | F6: 5 | H6: =B6+F6-1 -> 45665 | I6: 9 | J6: =H6+I6+1 -> 45675 | K6: AE
A7: 1738 | B7: 45662 | D7: Mastite clinica | F7: 5 | H7: =B7+F7-1 -> 45666 | I7: 3 | J7: =H7+I7+1 -> 45670 | L7: AD
A8: 3677 | B8: 45663 | D8: Mast jet | F8: 5 | H8: =B8+F8-1 -> 45667 | I8: 9 | J8: =H8+I8+1 -> 45677 | M8: PE
A9: 3745 | B9: 45663 | D9: Mastite clinica | F9: 5 | H9: =B9+F9-1 -> 45667 | I9: 3 | J9: =H9+I9+1 -> 45671 | M9: PE
A10: 3787 | B10: 45664 | D10: Mastite clinica | F10: 5 | H10: =B10+F10-1 -> 45668 | I10: 3 | J10: =H10+I10+1 -> 45672 | K10: AE
A11: 3754 | B11: 45664 | D11: Ubrolexin | F11: 5 | H11: =B11+F11-1 -> 45668 | I11: 5 | J11: =H11+I11+1 -> 45674 | K11: AE
A12: 3621 | B12: 45664 | D12: Ubrolexin | F12: 5 | H12: =B12+F12-1 -> 45668 | I12: 5 | J12: =H12+I12+1 -> 45674 | L12: AD
A13: 2949 | B13: 45664 | D13: Ubrolexin | F13: 5 | H13: =B13+F13-1 -> 45668 | I13: 5 | J13: =H13+I13+1 -> 45674 | K13: AE | M13: PE
A14: 296 | B14: 45664 | D14: Ubrolexin | F14: 5 | H14: =B14+F14-1 -> 45668 | I14: 5 | J14: =H14+I14+1 -> 45674 | M14: PE
A15: 2906 | B15: 45665 | D15: Mastite clinica | F15: 5 | H15: =B15+F15-1 -> 45669 | I15: 3 | J15: =H15+I15+1 -> 45673 | K15: AE
A16: 3787 | B16: 45665 | D16: Ubrolexin | F16: 5 | H16: =B16+F16-1 -> 45669 | I16: 5 | J16: =H16+I16+1 -> 45675 | L16: AD
A17: 2696 | B17: 45666 | D17: Ubrolexin | F17: 5 | H17: =B17+F17-1 -> 45670 | I17: 5 | J17: =H17+I17+1 -> 45676 | N17: PD
A18: 1185 | B18: 45668 | D18: Mastite clinica | F18: 5 | H18: =B18+F18-1 -> 45672 | I18: 3 | J18: =H18+I18+1 -> 45676 | K18: AE | L18: AD
A19: 3304 | B19: 45668 | D19: MASTJET | F19: 5 | H19: =B19+F19-1 -> 45672 | I19: 9 | J19: =H19+I19+1 -> 45682 | K19: AE | M19: PE
A20: 2238 | B20: 45669 | D20: ubrolexin | F20: 5 | H20: =B20+F20-1 -> 45673 | I20: 3 | J20: =H20+I20+1 -> 45677 | K20: AE | M20: PE | N20: PD
A21: 4192 | B21: 45670 | D21: Mastite clinica | F21: 5 | H21: =B21+F21-1 -> 45674 | I21: 3 | J21: =H21+I21+1 -> 45678 | N21: PD
A22: 1119 | B22: 45670 | D22: Mastite clinica | F22: 5 | H22: =B22+F22-1 -> 45674 | I22: 3 | J22: =H22+I22+1 -> 45678 | M22: PE | N22: PD
A23: 4202 | B23: 45670 | D23: Mastite clinica | F23: 5 | H23: =B23+F23-1 -> 45674 | I23: 3 | J23: =H23+I23+1 -> 45678 | K23: AE
A24: 3278 | B24: 45671 | D24: Mastite clinica | F24: 5 | H24: =B24+F24-1 -> 45675 | I24: 3 | J24: =H24+I24+1 -> 45679 | L24: AD
A25: 4206 | B25: 45671 | D25: Mastite clinica | F25: 5 | H25: =B25+F25-1 -> 45675 | I25: 3 | J25: =H25+I25+1 -> 45679 | M25: PE
A26: 1749 | B26: 45672 | D26: Ubrolexin | F26: 5 | H26: =B26+F26-1 -> 45676 | I26: 5 | J26: =H26+I26+1 -> 45682 | N26: PD
A27: 3617 | B27: 45672 | D27: Mastite clinica | F27: 5 | H27: =B27+F27-1 -> 45676 | I27: 3 | J27: =H27+I27+1 -> 45680 | M27: PE
A28: 3512 | B28: 45674 | D28: Mastite clinica | F28: 5 | H28: =B28+F28-1 -> 45678 | I28: 3 | J28: =H28+I28+1 -> 45682 | K28: AE
A29: 1180 | B29: 45673 | D29: Mastite clinica | F29: 5 | H29: =B29+F29-1 -> 45677 | I29: 3 | J29: =H29+I29+1 -> 45681 | K29: AE
A30: 3051 | B30: 45673 | D30: Mastite clinica | F30: 5 | H30: =B30+F30-1 -> 45677 | I30: 3 | J30: =H30+I30+1 -> 45681 | L30: AD
A31: 3110 | B31: 45674 | D31: Mastite clinica | F31: 5 | H31: =B31+F31-1 -> 45678 | I31: 3 | J31: =H31+I31+1 -> 45682 | L31: AD | N31: PD
A32: 1749 | B32: 45675 | D32: MASTJET | F32: 5 | H32: =B32+F32-1 -> 45679 | I32: 9 | J32: =H32+I32+1 -> 45689 | L32: AD | N32: PD
A33: 3568 | B33: 45675 | D33: Mastite clinica | F33: 5 | H33: =B33+F33-1 -> 45679 | I33: 3 | J33: =H33+I33+1 -> 45683 | K33: AE | N33: PD
A34: 2488 | B34: 45675 | D34: Mastite clinica | F34: 5 | H34: =B34+F34-1 -> 45679 | I34: 3 | J34: =H34+I34+1 -> 45683 | L34: AD
A35: 3901 | B35: 45675 | D35: Mastite clinica | F35: 5 | H35: =B35+F35-1 -> 45679 | I35: 3 | J35: =H35+I35+1 -> 45683 | N35: PD
A36: 578 | B36: 45676 | D36: Mastite clinica | F36: 5 | H36: =B36+F36-1 -> 45680 | I36: 3 | J36: =H36+I36+1 -> 45684 | N36: PD
A37: 3986 | B37: 45676 | D37: Mastite clinica | F37: 5 | H37: =B37+F37-1 -> 45680 | I37: 3 | J37: =H37+I37+1 -> 45684 | L37: AD
A38: 2949 | B38: 45677 | D38: mastjet | F38: 5 | H38: =B38+F38-1 -> 45681 | I38: 9 | J38: =H38+I38+1 -> 45691 | L38: AD
A39: 3791 | B39: 45677 | D39: Ubrolexin | F39: 5 | H39: =B39+F39-1 -> 45681 | I39: 5 | J39: =H39+I39+1 -> 45687 | K39: AE | M39: PE | N39: PD
A40: 4054 | B40: 45677 | D40: Mastite clinica | F40: 5 | H40: =B40+F40-1 -> 45681 | I40: 3 | J40: =H40+I40+1 -> 45685 | L40: AD
...

Sheet HIPERQUERATOSE 26
A1: 46143
A2: Numero vaca | B2: AD | C2: AE | D2: PÉ | E2: PD | F2: Score sujidade | G2: MÉDIA
A3: 0 | B3: 2 | C3: 2 | D3: 1 | E3: 1 | F3: 3 | G3: 1.5
A4: 218 | B4: 3 | C4: 1 | D4: 2 | E4: 1 | F4: 3 | G4: 1.75
A5: 301 | B5: 2 | C5: 1 | D5: 1 | E5: 2 | F5: 3 | G5: 1.5
A6: 574 | B6: 1 | C6: 1 | D6: 1 | E6: 1 | F6: 3 | G6: 1
A7: 649 | B7: 2 | C7: 3 | D7: 3 | E7: 1 | F7: 3 | G7: 2.25
A8: 650 | B8: 2 | C8: 2 | D8: 3 | E8: 3 | F8: 3 | G8: 2.5
A9: 653 | B9: 3 | C9: 2 | D9: 2 | E9: 1 | F9: 3 | G9: 2
A10: 657 | B10: 3 | C10: 1 | D10: 2 | E10: 0 | F10: 3 | G10: 1.5
A11: 850 | B11: 0 | C11: 2 | D11: 2 | E11: 0 | F11: 3 | G11: 1
A12: 892 | B12: 1 | C12: 1 | D12: 1 | E12: 1 | F12: 3 | G12: 1
A13: 1142 | B13: 1 | C13: 1 | D13: 1 | E13: 4 | F13: 2 | G13: 1.75
A14: 1160 | B14: 2 | C14: 2 | D14: 1 | E14: 1 | F14: 3 | G14: 1.5
... A1542: 5826 | B1542: 1 | C1542: 1 | D1542: 2 | E1542: 2 | F1542: 3 | G1542: 1.5

Sheet 2026
A1: VACA | B1: INÍCIO TRATAMENTO | D1: INTRAMAMÁRIO | F1: DIAS APP | H1: DATA FINAL | I1: CARÊNCIA | J1: RETORNO | K1: TETO EM TRATAMENTO | O1: GRAU HIPERQUERATOSE
A2: 3480 | B2: 46024 | D2: Mastite clinica | F2: 5 | H2: 46028 | I2: 3 | J2: 46032 | N2: PD | O2: =VLOOKUP(A2,'HIPERQUERATOSE 26'!$A$2:$G$1542,7,1) -> 1
A3: 3423 | B3: 46024 | D3: Mastite clinica | F3: 5 | H3: 46028 | I3: 3 | J3: 46032 | N3: PD | O3: =VLOOKUP(A3,'HIPERQUERATOSE 26'!$A$2:$G$1542,7,1) -> 3.25
A4: 4216 | B4: 46024 | D4: Mastite clinica | F4: 5 | H4: 46028 | I4: 3 | J4: 46032 | N4: PD | O4: =VLOOKUP(A4,'HIPERQUERATOSE 26'!$A$2:$G$1542,7,1) -> 3
A5: 1203 | B5: 46024 | D5: MASTGEN | F5: 5 | H5: 46028 | I5: 5 | J5: 46034 | K5: AE | O5: =VLOOKUP(A5,'HIPERQUERATOSE 26'!$A$2:$G$1542,7,1) -> 2.25
A6: 3718 | B6: 46025 | D6: Mastite clinica | F6: 5 | H6: 46029 | I6: 3 | J6: 46033 | N6: PD | O6: =VLOOKUP(A6,'HIPERQUERATOSE 26'!$A$2:$G$1542,7,1) -> 1.5
A7: 3862 | B7: 46025 | D7: Mastite clinica | F7: 5 | H7: 46029 | I7: 3 | J7: 46033 | L7: AD | O7: =VLOOKUP(A7,'HIPERQUERATOSE 26'!$A$2:$G$1542,7,1) -> 1.5
A8: 4648 | B8: 46025 | D8: Mastite clinica | F8: 5 | H8: 46029 | I8: 3 | J8: 46033 | N8: PD | O8: =VLOOKUP(A8,'HIPERQUERATOSE 26'!$A$2:$G$1542,7,1) -> 1.5
A9: 4469 | B9: 46026 | D9: Mastite clinica | F9: 5 | H9: 46030 | I9: 3 | J9: 46034 | L9: AD | O9: =VLOOKUP(A9,'HIPERQUERATOSE 26'!$A$2:$G$1542,7,1) -> 1.75
A10: 3397 | B10: 46027 | D10: RILEXINE | F10: 5 | H10: 46031 | I10: 5 | J10: 46037 | K10: AE | O10: =VLOOKUP(A10,'HIPERQUERATOSE 26'!$A$2:$G$1542,7,1) -> 3
A11: 5356 | B11: 46027 | D11: Mastite clinica | F11: 5 | H11: 46031 | I11: 3 | J11: 46035 | M11: PE | O11: =VLOOKUP(A11,'HIPERQUERATOSE 26'!$A$2:$G$1542,7,1) -> 1.5
A12: 4817 | B12: 46028 | D12: MASTJET | F12: 3 | H12: 46030 | I12: 9 | J12: 46040 | L12: AD | O12: =VLOOKUP(A12,'HIPERQUERATOSE 26'!$A$2:$G$1542,7,1) -> 1
A13: 3902 | B13: 46028 | D13: MASTJET | F13: 5 | H13: 46032 | I13: 9 | J13: 46042 | M13: PE | O13: =VLOOKUP(A13,'HIPERQUERATOSE 26'!$A$2:$G$1542,7,1) -> 3
A14: 3594 | B14: 46028 | D14: MASTJET | F14: 5 | H14: 46032 | I14: 9 | J14: 46042 | N14: PD | O14: =VLOOKUP(A14,'HIPERQUERATOSE 26'!$A$2:$G$1542,7,1) -> 1.25
A15: 3591 | B15: 46028 | D15: Mastgen | F15: 5 | H15: 46032 | I15: 5 | J15: 46038 | O15: =VLOOKUP(A15,'HIPERQUERATOSE 26'!$A$2:$G$1542,7,1) -> 1
A16: 4324 | B16: 46029 | D16: Mastite clinica | F16: 5 | H16: 46033 | I16: 3 | J16: 46037 | M16: PE | O16: =VLOOKUP(A16,'HIPERQUERATOSE 26'!$A$2:$G$1542,7,1) -> 2.75
A17: 3526 | B17: 46031 | D17: Mastgen | F17: 5 | H17: 46035 | I17: 5 | J17: 46041 | N17: PD | O17: =VLOOKUP(A17,'HIPERQUERATOSE 26'!$A$2:$G$1542,7,1) -> 1
A18: 3423 | B18: 46032 | D18: MASTGEN | F18: 5 | H18: 46036 | I18: 5 | J18: 46042 | N18: PD | O18: =VLOOKUP(A18,'HIPERQUERATOSE 26'!$A$2:$G$1542,7,1) -> 3.25
A19: 4129 | B19: 46033 | D19: Mastite clinica | F19: 5 | H19: 46037 | I19: 5 | J19: 46043 | L19: AD | O19: =VLOOKUP(A19,'HIPERQUERATOSE 26'!$A$2:$G$1542,7,1) -> 1
A20: 5177 | B20: 46033 | D20: Mastite clinica | F20: 5 | H20: 46037 | I20: 5 | J20: 46043 | N20: PD | O20: =VLOOKUP(A20,'HIPERQUERATOSE 26'!$A$2:$G$1542,7,1) -> 1.25
A21: 4058 | B21: 46034 | D21: MASTJET | F21: 4 | H21: 46037 | I21: 9 | J21: 46047 | K21: AE | O21: =VLOOKUP(A21,'HIPERQUERATOSE 26'!$A$2:$G$1542,7,1) -> 1.5
A22: 3554 | B22: 46035 | D22: Mastite clinica | F22: 5 | H22: 46039 | I22: 3 | J22: 46043 | K22: AE | O22: =VLOOKUP(A22,'HIPERQUERATOSE 26'!$A$2:$G$1542,7,1) -> 1
A23: 4452 | B23: 46035 | D23: Mastite clinica | F23: 5 | H23: 46039 | I23: 3 | J23: 46043 | K23: AE | O23: =VLOOKUP(A23,'HIPERQUERATOSE 26'!$A$2:$G$1542,7,1) -> 2
A24: 4667 | B24: 46035 | D24: Mastite clinica | F24: 5 | H24: 46039 | I24: 3 | J24: 46043 | N24: PD | O24: =VLOOKUP(A24,'HIPERQUERATOSE 26'!$A$2:$G$1542,7,1) -> 2.25
A25: 5250 | B25: 46036 | D25: Mastite clinica | F25: 5 | H25: 46040 | I25: 3 | J25: 46044 | M25: PE | O25: =VLOOKUP(A25,'HIPERQUERATOSE 26'!$A$2:$G$1542,7,1) -> 1.5
A26: 3746 | B26: 46036 | D26: MASTJET | F26: 5 | H26: 46040 | I26: 9 | J26: 46050 | M26: PE | O26: =VLOOKUP(A26,'HIPERQUERATOSE 26'!$A$2:$G$1542,7,1) -> 2.25
A27: 5194 | B27: 46037 | D27: Mastite clinica | F27: 5 | H27: 46041 | I27: 3 | J27: 46045 | N27: PD | O27: =VLOOKUP(A27,'HIPERQUERATOSE 26'!$A$2:$G$1542,7,1) -> 1
A28: 3554 | B28: 46037 | D28: MASTGEN | F28: 5 | H28: 46041 | I28: 9 | J28: 46051 | K28: AE | O28: =VLOOKUP(A28,'HIPERQUERATOSE 26'!$A$2:$G$1542,7,1) -> 1
A29: 4773 | B29: 46037 | D29: Mastite clinica | F29: 5 | H29: 46041 | I29: 3 | J29: 46045 | M29: PE | O29: =VLOOKUP(A29,'HIPERQUERATOSE 26'!$A$2:$G$1542,7,1) -> 2
A30: 4501 | B30: 46037 | D30: Mastite clinica | F30: 5 | H30: 46041 | I30: 3 | J30: 46045 | L30: AD | O30: =VLOOKUP(A30,'HIPERQUERATOSE 26'!$A$2:$G$1542,7,1) -> 2.5
A31: 5209 | B31: 46038 | D31: COBACTAM | F31: 4 | H31: 46041 | I31: 3 | J31: 46045 | L31: AD | O31: =VLOOKUP(A31,'HIPERQUERATOSE 26'!$A$2:$G$1542,7,1) -> 1
A32: 4452 | B32: 46038 | D32: COBACTAM | F32: 4 | H32: 46041 | I32: 3 | J32: 46045 | K32: AE | O32: =VLOOKUP(A32,'HIPERQUERATOSE 26'!$A$2:$G$1542,7,1) -> 2
A33: 4385 | B33: 46038 | D33: COBACTAM | F33: 4 | H33: 46041 | I33: 3 | J33: 46045 | M33: PE | O33: =VLOOKUP(A33,'HIPERQUERATOSE 26'!$A$2:$G$1542,7,1) -> 1.25
A34: 4058 | B34: 46038 | D34: COBACTAM | F34: 4 | H34: 46041 | I34: 3 | J34: 46045 | K34: AE | O34: =VLOOKUP(A34,'HIPERQUERATOSE 26'!$A$2:$G$1542,7,1) -> 1.5
A35: 4829 | B35: 46039 | D35: COBACTAM | F35: 4 | H35: 46042 | I35: 3 | J35: 46046 | M35: PE | O35: =VLOOKUP(A35,'HIPERQUERATOSE 26'!$A$2:$G$1542,7,1) -> 1
A36: 2885 | B36: 46039 | D36: SINULOX | F36: 4 | H36: 46042 | I36: 4 | J36: 46046 | N36: PD | O36: =VLOOKUP(A36,'HIPERQUERATOSE 26'!$A$2:$G$1542,7,1) -> 1
A37: 3072 | B37: 46039 | D37: COBACTAM | F37: 4 | H37: 46042 | I37: 3 | J37: 46046 | K37: AE | O37: =VLOOKUP(A37,'HIPERQUERATOSE 26'!$A$2:$G$1542,7,1) -> 1.25
A38: 4026 | B38: 46039 | D38: SINULOX | F38: 4 | H38: 46042 | I38: 4 | J38: 46046 | L38: AD | O38: =VLOOKUP(A38,'HIPERQUERATOSE 26'!$A$2:$G$1542,7,1) -> 2.25
A39: 4578 | B39: 46039 | D39: COBACTAM | F39: 4 | H39: 46042 | I39: 3 | J39: 46046 | L39: AD | O39: =VLOOKUP(A39,'HIPERQUERATOSE 26'!$A$2:$G$1542,7,1) -> 1.25
A40: 4111 | B40: 46038 | D40: COBACTAM | F40: 4 | H40: 46041 | I40: 3 | J40: 46045 | N40: PD | O40: =VLOOKUP(A40,'HIPERQUERATOSE 26'!$A$2:$G$1542,7,1) -> 2
...

Sheet Planilha1
A2: 3110
A3: 1746
A4: 2385
A5: 2570
A6: 2760
A7: 2760
A8: 2800
A9: 2885
A10: 2889
A11: 2894
A12: 3020
A13: 3064
... A115: 5829

Sheet SECAGEM
A1: Lote | B1: Brinco | C1: DEL | D1: LACT | E1: ÚltTratSeca | F1: DATA SECA | G1: StatRepro | H1: DiasCarenLeite | I1: DtÚltParto | J1: retorno
A2: 6 | B2: 3494 | C2: 686 | D2: 2 | E2: Cepravin | F2: 45435 | G2: Sold | H2: 0 | I2: 45489 | J2: =I2+3 -> 45492 | L2: =J2-F2 -> 57
A3: 6 | B3: 3015 | C3: 670 | D3: 3 | E3: Cepravin | F3: 45442 | G3: Sold | H3: 0 | I3: 45504 | J3: =I3+3 -> 45507 | L3: =J3-F3 -> 65
A4: 6 | B4: 3026 | C4: 579 | D4: 3 | E4: Cepravin | F4: 45442 | G4: Sold | H4: 0 | I4: 45505 | J4: =I4+3 -> 45508 | L4: =J4-F4 -> 66
A5: 10 | B5: 3391 | C5: 532 | D5: 2 | E5: Cepravin | F5: 45456 | G5: Sold | H5: 0 | I5: 45573 | J5: =I5+3 -> 45576 | L5: =J5-F5 -> 120
A6: 10 | B6: 3546 | C6: 484 | D6: 2 | E6: Cepravin | F6: 45463 | G6: Sold | H6: 0 | I6: 45524 | J6: =I6+3 -> 45527 | L6: =J6-F6 -> 64
A7: 6 | B7: 3690 | C7: 486 | D7: 2 | E7: Cepravin | F7: 45463 | G7: Sold | H7: 0 | I7: 45528 | J7: =I7+3 -> 45531 | L7: =J7-F7 -> 68
A8: 6 | B8: 2952 | C8: 633 | D8: 3 | E8: Teatseal | F8: 45477 | G8: Sold | H8: 0 | I8: 45541 | J8: =I8+3 -> 45544 | L8: =J8-F8 -> 67
A9: 10 | B9: 2020 | C9: 298 | D9: 5 | E9: Teatseal | F9: 45477 | G9: Sold | H9: 0 | I9: 45634 | J9: =I9+3 -> 45637 | L9: =J9-F9 -> 160
A10: 2 | B10: 3573 | C10: 160 | D10: 3 | E10: Teatseal | F10: 45484 | G10: Prenha | H10: 0 | I10: 46099 | J10: =I10+3 -> 46102 | L10: =J10-F10 -> 618
A11: 6 | B11: 2018 | C11: 451 | D11: 6 | E11: Teatseal | F11: 45491 | G11: Sold | H11: 0 | I11: 45701 | J11: =I11+3 -> 45704 | L11: =J11-F11 -> 213
A12: 7 | B12: 2900 | C12: 306 | D12: 3 | E12: Teatseal | F12: 45498 | G12: Sold | H12: 0 | I12: 45564 | J12: =I12+3 -> 45567 | L12: =J12-F12 -> 69
A13: 6 | B13: 2767 | C13: 467 | D13: 3 | E13: Cepravin | F13: 45505 | G13: Sold | H13: 0 | I13: 45568 | J13: =I13+3 -> 45571 | L13: =J13-F13 -> 66
... A1331: 10 | B1331: 4906 | C1331: 6 | D1331: 2 | E1331: INTRASEC PLUS | F1331: 46218 | G1331: Fresca | H1331: 0 | I1331: 46253 | J1331: =I1331+3 -> 46256 | L1331: =J1331-F1331 -> 38

Sheet DOENÇAS GERAL
A1: DATA | B1: VACA | C1: DOENÇA | D1: MEDICAMENTO | E1: DIAS APLICAÇÃO | J1: RETORNO
A2: 46204 | B2: 5566 | C2: MASTITE | D2: TS + FORTGAL | E2: 1 | F2: 2 | G2: 3 | J2: 46210
A3: 46204 | B3: 4038 | C3: MASTITE | D3: TS + FORTGAL | E3: 1 | F3: 2 | G3: 3 | J3: 46210
A4: 46204 | B4: 2936 | C4: MASTITE | D4: TS+ KINETOMAX+FORCIL | E4: 1 | F4: 2 | G4: 3 | J4: 46211
A5: 46204 | B5: 4587 | C5: PIRO | D5: OUROTETRA+FERRODEX+B12 | E5: 1 | F5: 2 | G5: 3 | J5: 46228
A6: 46204 | B6: 3445 | C6: RETENÇÃO DE PLACENTA | D6: PENCIVET + SORO | E6: 1 | F6: 2 | G6: 3 | J6: 46211
A7: 46207 | B7: 5347 | C7: MASTITE | D7: KINETOMAX+ FORCIL | E7: 4 | F7: 5 | G7: 6 | J7: 46214
A8: 46207 | B8: 3759 | C8: MASTITE | D8: TOLFEDINE+FORCIL | E8: 4 | F8: 5 | G8: 6 | J8: 46214
A9: 46206 | B9: 5039 | C9: PNEUMONIA | D9: PENCIVET+ÓLEO CANFORADO | E9: 3 | F9: 4 | G9: 5 | J9: 46213
A10: 46207 | B10: 4394 | C10: MASTITE | D10: FORTGAL+MAXICAN | E10: 4 | F10: 5 | G10: 6 | J10: 46213
A11: 46207 | B11: 5232 | C11: MASTITE | D11: TS+OUROTETRA | E11: 4 | F11: 5 | G11: 6 | J11: 46231
A12: 46208 | B12: 2981 | C12: MASTITE | D12: FORTGAL+MAXICAN | E12: 5 | F12: 6 | G12: 7 | J12: 46214
A13: 46208 | B13: 2398 | C13: PNEUMONIA | D13: PENCIVET+SORO+MAXICAN | E13: 5 | F13: 6 | G13: 7 | J13: 46216
... A44: 46211 | B44: 4642 | C44: ABOMASO | D44: SORO+PENCIVET+MAXICAN | E44: 8 | F44: 9 | G44: 10 | J44: 46220
A45: 46212 | B45: 4407 | C45: ABOMASO | D45: KINETOMAX+MAXICAN | E45: 9 | F45: 10 | G45: 11 | H45: 12 | J45: 46221
A46: 46212 | B46: 4731 | C46: RETENÇÃO DE PLACENTA | D46: PENCIVET | E46: 9 | F46: 10 | G46: 11 | J46: 46221
A47: 46212 | B47: 4729 | C47: RETENÇÃO DE PLACENTA | D47: PENCIVET | E47: 9 | F47: 10 | G47: 11 | J47: 46221
A48: 46212 | B48: 4915 | C48: PNEUMONIA | D48: PENCIVET+ÓLEO+MAXICAN | E48: 9 | F48: 10 | G48: 11 | J48: 46221
A49: 46212 | B49: 3478 | C49: MASTITE | D49: KINETOMAX+FORCIL | E49: 9 | F49: 10 | G49: 11 | J49: 46221
A50: 46212 | B50: 4446 | C50: MASTITE | D50: FORTGAL+MAXICAN | E50: 9 | F50: 10 | G50: 11 | J50: 46221
A51: 46212 | B51: 3210 | C51: MASTITE | D51: TS+FORTGAL | E51: 9 | F51: 10 | G51: 11 | J51: 46219
A52: 46212 | B52: 5596 | C52: MASTITE | D52: TS+OUROTETRA | E52: 9 | F52: 10 | G52: 11 | J52: 46237
A53: 46212 | B53: 3193 | C53: PNEUMONIA | D53: SORO+PENCIVET | E53: 9 | F53: 10 | G53: 11 | J53: 46221
A54: 46212 | B54: 2856 | C54: PNEUMONIA | D54: KINETOMAX+ÓLEO+MAXICAN | E54: 9 | F54: 10 | G54: 11 | J54: 46221
A55: 46212 | B55: 4595 | C55: PIRO | D55: OUROTETRA+FERRODEX+B12 | E55: 9 | F55: 10 | G55: 11 | J55: 46237
A56: 46213 | B56: 3876 | C56: CASCO | D56: TILOFOR | E56: 10 | F56: 11 | G56: 12 | J56: 46218
A57: 46213 | B57: 4661 | C57: PNEUMONIA | D57: SORO+PENCIVET | E57: 10 | F57: 11 | G57: 12 | J57: 46222
... A85: 46223 | B85: 3997 | C85: ABOMASO | D85: PENCIVET | E85: 20 | F85: 21 | G85: 22 | J85: 46231
A86: 46223 | B86: PIRO | C86: PIRO | D86: OUROTETRA+FERRODEX+B12 | E86: 20 | F86: 21 | G86: 22 | J86: 46247
A87: 46224 | B87: 4823 | C87: MASTITE | D87: FORTGAL+METACAN | E87: 21 | F87: 22 | G87: 23 | J87: 46231
A88: 46224 | B88: 4928 | C88: PNEUMONIA | D88: PENCIVET+ÓLEO+MAXICAN | E88: 21 | F88: 22 | G88: 23 | J88: 46233
A89: 46224 | B89: 4456 | C89: MASTITE | D89: TS+OUROTETRA | E89: 21 | F89: 22 | G89: 23 | J89: 46249
A90: 46225 | B90: 3225 | C90: CASCO | D90: TILOFOR | E90: 22 | F90: 23 | G90: 24 | J90: 46231
A91: 46225 | B91: 3164 | C91: PIRO | D91: OUROTETRA+FERRODEX+B12 | E91: 22 | F91: 23 | G91: 24 | J91: 46250
A92: 46225 | B92: 3556 | C92: PIRO | D92: OUROTETRA+FERRODEX+B12 | E92: 22 | F92: 23 | G92: 24 | J92: 46250
A93: 46226 | B93: 5447 | C93: CASCO | D93: TILOFOR | E93: 23 | F93: 24 | G93: 25 | J93: 46232
A94: 46226 | B94: 2925 | C94: PNEUMONIA | D94: TILOFOR+MAXICAN | E94: 23 | F94: 24 | G94: 25 | J94: 46234
A95: 46227 | B95: 3263 | C95: PIRO | D95: KINETOMAX | E95: 24 | F95: 25 | G95: 26 | J95: 46234
A96: 46227 | B96: 3816 | C96: PNEUMONIA+CASCO | D96: TILOFOR+MAXICAN | E96: 24 | F96: 25 | G96: 26 | J96: 46235
A97: 46228 | B97: 4732 | C97: PNEUMONIA | D97: TILOFOR+SORO | E97: 25 | F97: 26 | G97: 27 | J97: 46234
...
